Workbook

Sheet Final
D1: Group 2 | E1: Product Backlog | R1: # | S1: ID | T1: Days | U1: Left Days | V1: Start Date | W1: End Date
D2: Rental Car Project | E2: "Europcar" | R2: Sprint 1 | S2: 1,2,5 | T2: =W2-V2 -> 28 | U2: =W2-F3 -> -43 | V2: 43552 | W2: 43580
D3: Deadline Estimate / Today | E3: 43623 | F3: =TODAY() -> 43623 | G3: Left days: | H3: =E3-F3 -> 0 | R3: Sprint 2 | S3: 3,4,6,8,9,11 | T3: =W3-V3 -> 21 | U3: =W3-F3 -> -22 | V3: 43580 | W3: 43601
D4: How many percent are done | E4: =COUNTA(Table1[Day 1],Table1[Day 2],Table1[Day 3])/(COUNTA(Table1[Estimate])*3)*100 -> 100 | G4: =IF(E4=100,"yeeees, we dit it :)","we didn't finised our project :(") -> yeeees, we dit it :) | R4: Sprint 3 | S4: 12.13 | T4: =W4-V4 -> 6 | U4: =W4-F3 -> -16 | V4: 43601 | W4: 43607 | Z4: Analyze and designe
D5: ? | E5: ? | R5: Sprint 4 | S5: 8,10,14 | T5: =W5-V5 -> 5 | U5: =W5-F3 -> -11 | V5: 43607 | W5: 43612 | Z5: Documentation
D6: ? | E6: ? | F6: ? | R6: Sprint 5 | S6: 7 | T6: =W6-V6 -> 3 | U6: =W6-F3 -> -8 | V6: 43612 | W6: 43615 | Z6: BurnDown Chart
D7: Number of hours Estimate/Actual | E7: =Table1[[#Totals],[Estimate]] -> 185 | F7: =SUM(Table1[[#Totals],[Day 1]:[Day 3]]) -> 183.45 | R7: Sprint 6 | S7: Doc | T7: =W7-V7 -> 4 | U7: =W7-F3 -> -4 | V7: 43615 | W7: 43619 | Z7: Goup contract
R8: Sprint 7 | S8: Doc | T8: =W8-V8 -> 4 | U8: =W8-F3 -> 0 | V8: 43619 | W8: 43623
A9: Product Backlog | R9: Total | T9: =SUBTOTAL(109,Table2[Days]) -> 71
A10: ID | B10: Priority | C10: Estimate | D10: Item | E10: Day 1 | F10: Day 2 | G10: Day 3
A11: 1 | B11: Critical | C11: 20 | D11: As a user, I want to be able to rent a car in order to drive. | E11: =Table14[[#This Row],[Day 1]] -> 15 | F11: =Table14[[#This Row],[Day 2]] -> 8 | G11: =Table14[[#This Row],[Day 3]] -> 9 | H11: +
A12: 2 | B12: High | C12: 15 | D12: As a user, I want to be able to select a certain type of vehicle in order to find a vehicle that suits my needs. | E12: ='Sprint 1'!F23 -> 10 | F12: ='Sprint 1'!G23 -> 8 | G12: ='Sprint 1'!H23 -> 6.5 | H12: +
A13: 3 | B13: Medium | C13: 10 | D13: As a user, I want to be able to select additional services in order to ease my journey. | E13: ='Sprint 2'!F11 -> 3.2 | F13: ='Sprint 2'!G11 -> 0.75 | G13: ='Sprint 2'!H11 -> 0.75 | H13: + | I13: Velocity Chart
A14: 4 | B14: Low | D14: As a user, I want the system to save my credentials in order to make it easier next time renting a vehicle.
A15: 5 | B15: High | C15: 20 | D15: As a user, I want to be able to select the number of days I want to rent the vehicle in order to reserve the vehicle. | E15: ='Sprint 1'!F31 -> 5 | F15: ='Sprint 1'!G31 -> 4.5 | G15: ='Sprint 1'!H31 -> 3.5 | H15: +
A16: 6 | B16: Mid low | C16: 10 | D16: As a user, I want to be able to see the pricing of different vehicles in order to select a vehicle inside my budget. | E16: ='Sprint 2'!F22 -> 2.5 | F16: ='Sprint 2'!G22 -> 3 | G16: ='Sprint 2'!H22 -> 1.5 | H16: +
A17: 7 | B17: Medium | C17: 5 | D17: As a user, I want to be able to cancel my reservation in order to not rent a vehicle. | E17: ='Sprint 5'!F11 -> 5 | F17: ='Sprint 5'!G11 -> 2 | G17: ='Sprint 5'!H11 -> 3
A18: 8 | B18: Low | C18: 15 | D18: As a user, I want to be notified if changes occur to my reservation, in order to be able to change my reservation | E18: ='Sprint 4'!F11 -> 7 | F18: ='Sprint 4'!G11 -> 5 | G18: ='Sprint 4'!H11 -> 3 | H18: +
A19: 9 | B19: High | C19: 25 | D19: As a user, I want to receive a booking confirmation by email, in order to have proof of reservation. | E19: ='Sprint 2'!F28 -> 4.25 | F19: ='Sprint 2'!G28 -> 2 | G19: ='Sprint 2'!H28 -> 1 | H19: +
A20: 10 | B20: Low | C20: 20 | D20: As an administrator, I want to be able to select the prices of different cars, in order to control prices. | E20: ='Sprint 4'!F17 -> 7 | F20: ='Sprint 4'!G17 -> 4 | G20: ='Sprint 4'!H17 -> 2 | H20: +
A21: 11 | B21: High | C21: 15 | D21: As an administrator, I want to be able to access my customers credentials in order to be able to contact them. | E21: ='Sprint 2'!F16 -> 4.5 | F21: ='Sprint 2'!G16 -> 2.5 | G21: ='Sprint 2'!H16 -> 3 | H21: +
A22: 12 | B22: High | C22: 10 | D22: As an administrator, I want to be able to see what vehicles are currently rented out, in order to see what is available. | E22: ='Sprint 3'!F11 -> 8 | F22: ='Sprint 3'!G11 -> 6 | G22: ='Sprint 3'!H11 -> 5.5 | H22: +
A23: 13 | B23: Mid low | C23: 10 | D23: As an administrator, I want to be able to select extra services provided, in order to ease the journey of the customer. | E23: ='Sprint 3'!F19 -> 1 | F23: =Table14[[#This Row],[Day 2]] -> 8 | G23: =Table14[[#This Row],[Day 3]] -> 6.5 | H23: +
A24: 14 | B24: Medium | C24: 10 | D24: As a user, I want to be able to add money to my wallet | E24: ='Sprint 4'!F23 -> 8 | F24: ='Sprint 4'!G23 -> 3 | G24: ='Sprint 4'!H23 -> 1 | H24: +
A25: Total | C25: =SUBTOTAL(109,Table1[Estimate]) -> 185 | E25: =SUBTOTAL(109,Table1[Day 1]) -> 80.45 | F25: =SUBTOTAL(109,Table1[Day 2]) -> 56.75 | G25: =SUBTOTAL(109,Table1[Day 3]) -> 46.25
E26: =SUM(Table1[[#Totals],[Day 1]:[Day 3]]) -> 183.45

Sheet Sprint 1
E1: Group 2 | F1: Product Backlog
E2: Rental Car Project | F2: "Europcar"
E3: Deadline Estimate / Today | F3: 43623 | G3: =TODAY() -> 43623 | H3: Left days: | I3: =F3-G3 -> 0
E4: How many percent are done | F4: =(COUNTA(F12:F22,F24:F30,F32:F35,G12:G22,G24:G30,G32:G35,H12:H22,H24:H30,H32:H35))/(COUNTA(E12:E22,E24:E30,E32:E35)*3)*100 -> 100
E5: ? | F5: ? | H5: Done
E6: ? | F6: ? | G6: ? | H6: In Progres
E7: Number of hours Estimate/Actual | F7: =Table14[[#Totals],[Estimate]] -> 55 | G7: =SUM(Table14[[#Totals],[Day 1]:[Day 3]]) -> 69.5 | H7: Not Started
A9: Product Backlog
A10: ID | B10: Priority | C10: Responsible | D10: Estimate | E10: Item | F10: Day 1 | G10: Day 2 | H10: Day 3
A11: 1 | B11: Critical | D11: =Final!C11 -> 20 | E11: As a user, I want to be able to rent a car in order to drive. | F11: =SUM(F12:F22) -> 15 | G11: =SUM(G12:G22) -> 8 | H11: =SUM(H12:H22) -> 9
C12: Justinas | E12: Use case diagram and description | F12: 1 | G12: 1 | H12: 0
C13: Justinas | E13: Sequence Diagram | F13: 1 | G13: 0 | H13: 0 | J13: Velocity Chart
C14: Justinas | E14: Activity Diagram | F14: 1 | G14: 0 | H14: 0
C15: Justinas | E15: Create a domain model | F15: 0 | G15: 2 | H15: 0
C16: Justinas | E16: Create a logical model | F16: 0 | G16: 1 | H16: 0
C17: Justinas | E17: Create the user class | F17: 0 | G17: 0 | H17: 1
C18: Justinas | E18: Create the car class | F18: 0 | G18: 0 | H18: 1
C19: Justinas | E19: Create the database | F19: 5 | G19: 0 | H19: 0
C20: Justinas | E20: Generate some data for testing | F20: 3 | G20: 4 | H20: 0
C21: Justinas | E21: Program the server to give car list | F21: 2 | G21: 0 | H21: 3
C22: Justinas | E22: Program the client renting | F22: 2 | G22: 0 | H22: 4
A23: 2 | B23: High | D23: =Final!C12 -> 15 | E23: As a user, I want to be able to select a certain type of vehicle in order to find a vehicle that suits my needs. | F23: =SUM(F24:F30) -> 10 | G23: =SUM(G24:G30) -> 8 | H23: =SUM(H24:H30) -> 6.5
C24: Nicoleta\Dima | E24: Use Case Diagram | F24: 0.5 | G24: 0.5 | H24: 0.5
C25: Nicoleta | E25: Use Case Descrition | F25: 1 | G25: 1 | H25: 1
C26: Nicoleta | E26: Activity Diagram | F26: 0.5 | G26: 0.5 | H26: 0.5
C27: Dima | E27: Class Diagram | F27: 1 | G27: 1 | H27: 0.5
C28: Dima | E28: Create GUI | F28: 3 | G28: 2 | H28: 1
C29: Dima | E29: Create connection between 4 windows in GUI(Login,Registration, Search Car Option as a Guest and Search Car Option) | F29: 3 | G29: 3 | H29: 2
E30: Testing | F30: 1 | G30: 0 | H30: 1
A31: 5 | B31: High | C31: Simona | D31: =Final!C15 -> 20 | E31: As a user, I want to be able to select the number of days I want to rent the vehicle in order to reserve the vehicle. | F31: =SUM(F32:F35) -> 5 | G31: =SUM(G32:G35) -> 4.5 | H31: =SUM(H32:H35) -> 3.5
C32: Justinas | E32: Use Case Diagram | F32: 0.5 | G32: 0.5 | H32: 0.5
C33: Nicoleta | E33: Use Case Diagram | F33: 2 | G33: 2 | H33: 1
C34: Dima | E34: Use Case Diagram | F34: 1 | G34: 1 | H34: 1
C35: Dima | E35: Use Case Diagram | F35: 1.5 | G35: 1 | H35: 1
A36: Total | D36: =SUBTOTAL(109,D11,D23,D31) -> 55 | F36: =SUBTOTAL(109,F11,F23,F31) -> 30 | G36: =SUBTOTAL(109,G11,G23,G31) -> 20.5 | H36: =SUBTOTAL(109,H11,H23,H31) -> 19
E37: =SUM(Table14[[#Totals],[Day 1]:[Day 3]]) -> 69.5

Sheet Sprint 2
E1: Group 2 | F1: Product Backlog
E2: Rental Car Project | F2: "Europcar"
E3: Deadline Estimate / Today | F3: 43623 | G3: =TODAY() -> 43623 | H3: Left days: | I3: =F3-G3 -> 0
E4: How many percent are done | F4: =(COUNTA(F12:F15,F17:F21,F23:F27,F29:F33,G12:G15,G17:G21,G23:G27,,G29:G33,H12:H15,H17:H21,H23:H27,H29:H33))/(COUNTA(E12:E15,E17:E21,E23:E27,E29:E33)*3)*100 -> 102.08333
E5: ? | F5: ? | H5: Done
E6: ? | F6: ? | G6: ? | H6: In Progres
E7: Number of hours Estimate/Actual | F7: =Table145[[#Totals],[Estimate]] -> 60 | G7: =SUM(Table145[[#Totals],[Day 1]:[Day 3]]) -> 28.95 | H7: Not Started
A9: Product Backlog
A10: ID | B10: Priority | C10: Responsible | D10: Estimate | E10: Item | F10: Day 1 | G10: Day 2 | H10: Day 3
A11: 3 | B11: Medium | C11: Nicoleta | D11: =Final!C13 -> 10 | E11: As a user, I want to be able to select additional services in order to easy my journey | F11: =SUM(F12:F15) -> 3.2 | G11: =SUM(G12:G15) -> 0.75 | H11: =SUM(H12:H15) -> 0.75
E12: Uase case diagram | F12: 0.2 | G12: 0.5 | H12: 0
E13: Activity Diagram | F13: 2 | G13: 0 | H13: 0.5 | J13: Velocity Chart
E14: Create GUI | F14: 1 | G14: 0.25 | H14: 0.25
A16: 11 | B16: High | C16: Dima | D16: =Final!C21 -> 15 | E16: As an administrator, I want to be able to access my customers credentials in order to be able to contact them. | F16: =SUM(F17:F21) -> 4.5 | G16: =SUM(G17:G21) -> 2.5 | H16: =SUM(H17:H21) -> 3
E17: Create Booked tab for customers who booket at least one time | F17: 2 | G17: 2 | H17: 2
E18: Get Data from database and create SQL statement | F18: 1 | G18: 0 | H18: 0
E19: Testing | F19: 1 | G19: 0 | H19: 1
E20: Documentation | F20: 0.5 | G20: 0.5 | H20: 0
A22: 6 | B22: High | C22: Nicoleta | D22: =Final!C16 -> 10 | E22: As a user, I want to be able to see the pricing of different vehicles in order to select a vehicle inside my budget. | F22: =SUM(F23:F27) -> 2.5 | G22: =SUM(G23:G27) -> 3 | H22: =SUM(H23:H27) -> 1.5
E23: Activity Diagram | F23: 1 | G23: 1 | H23: 0.5
E24: Use Case diagram | F24: 0.25 | G24: 0 | H24: 0
E25: Use case description | F25: 0.25 | G25: 0 | H25: 0
E26: Class Diagram | F26: 1 | G26: 2 | H26: 1
A28: 9 | B28: High | C28: Justinas | D28: =Final!C19 -> 25 | E28: As a user, I want to receive a booking confirmation by email, in order to have proof of reservation. | F28: =SUM(F29:F33) -> 4.25 | G28: =SUM(G29:G33) -> 2 | H28: =SUM(H29:H33) -> 1
E29: Update the use case diagram | F29: 1 | G29: 1 | H29: 0
E30: Update the sequence diagram | F30: 1 | G30: 0 | H30: 1
E31: Implement a notification that an email is sent | F31: 1 | G31: 1 | H31: 0
B32: low | E32: Create SMTP or implement an existing one | F32: 0.25 | G32: 0 | H32: 0
B33: low | E33: Create the send an email method | F33: 1 | G33: 0 | H33: 0
A34: Total | D34: =SUBTOTAL(109,Table145[Estimate]) -> 60 | F34: =SUM(F11,F16,F22,F28) -> 14.45 | G34: =SUM(G11,G16,G22,G28) -> 8.25 | H34: =SUM(H11,H16,H22,H28) -> 6.25
F35: =SUM(Table145[[#Totals],[Day 1]:[Day 3]]) -> 28.95

Sheet Sprint 3
E1: Group 2 | F1: Product Backlog
E2: Rental Car Project | F2: "Europcar"
E3: Deadline Estimate / Today | F3: 43623 | G3: =TODAY() -> 43623 | H3: Left days: | I3: =F3-G3 -> 0
E4: How many percent are done | F4: =(COUNTA(F12:F18,F20:F22,G12:G18,G20:G22,H12:H18,H20:H22))/(COUNTA(E12:E18,E20:E22)*3)*100 -> 90
E5: ? | F5: ? | H5: Done
E6: ? | F6: ? | G6: ? | H6: In Progres
E7: Number of hours Estimate/Actual | F7: =Table1456[[#Totals],[Estimate]] -> 20 | G7: =SUM(Table1456[[#Totals],[Day 1]:[Day 3]]) -> 26.5 | H7: Not Started
A9: Product Backlog
A10: ID | B10: Priority | C10: Responsible | D10: Estimate | E10: Item | F10: Day 1 | G10: Day 2 | H10: Day 3
A11: 12 | B11: Medium | C11: Dima/Justinas | D11: =Final!C22 -> 10 | E11: As an administrator, I want to be able to see what vehicles are currently rented out, in order to see what is available. | F11: =SUM(F12:F18) -> 8 | G11: =SUM(G12:G18) -> 6 | H11: =SUM(H12:H18) -> 5.5
E12: Use case diagram | F12: 1 | G12: 1 | H12: 1
E13: Activity diagram | F13: 1 | G13: 1 | H13: 1 | J13: Velocity Chart
E14: Sql statements | F14: 2 | G14: 1 | H14: 0.5
E15: Available Cars Tab | F15: 2 | G15: 2 | H15: 1
E16: Booked Cars Tab | F16: 2 | G16: 1 | H16: 0.5
E17: Testing each case | F17: 0 | G17: 0 | H17: 1.5
E18: Documentation
A19: 13 | B19: Mid low | C19: Nicoleta | D19: =Final!C23 -> 10 | E19: As an administrator, I want to be able to select extra services provided, in order to ease the journey of the customer. | F19: =SUM(F20:F22) -> 1 | G19: =SUM(G20:G22) -> 3 | H19: =SUM(H20:H22) -> 3
E20: Activity diagram | F20: 0 | G20: 1 | H20: 1
E21: Use case diagram | F21: 0 | G21: 1 | H21: 1
E22: GUI | F22: 1 | G22: 1 | H22: 1
A23: Total | D23: =SUBTOTAL(109,Table1456[Estimate]) -> 20 | F23: =SUM(F12:F18,F20:F22) -> 9 | G23: =SUM(G12:G18,G20:G22) -> 9 | H23: =SUM(H12:H18,H20:H22) -> 8.5
F24: =SUM(Table1456[[#Totals],[Day 1]:[Day 3]]) -> 26.5

Sheet Sprint 4
E1: Group 2 | F1: Product Backlog
E2: Rental Car Project | F2: "Europcar"
E3: Deadline Estimate / Today | F3: 43623 | G3: =TODAY() -> 43623 | H3: Left days: | I3: =F3-G3 -> 0
E4: How many percent are done | F4: =(COUNTA(F12:F16,F18:F22,F24:F28,G12:G16,G18:G22,G24:G28,H12:H16,H18:H22,H24:H28))/(COUNTA(E12:E16,E18:E22,E24:E28)*3)*100 -> 100
E5: ? | F5: ? | H5: Done
E6: ? | F6: ? | G6: ? | H6: In Progres
E7: Number of hours Estimate/Actual | F7: =Table14567[[#Totals],[Estimate]] -> 45 | G7: =SUM(Table14567[[#Totals],[Day 1]:[Day 3]]) -> 40 | H7: Not Started
A9: Product Backlog
A10: ID | B10: Priority | C10: Responsible | D10: Estimate | E10: Item | F10: Day 1 | G10: Day 2 | H10: Day 3
A11: 8 | B11: Low | C11: Justinas | D11: =Final!C18 -> 15 | E11: As a user, I want to be notified if changes occur to my reservation, in order to be able to change my reservation | F11: =SUM(F12:F16) -> 7 | G11: =SUM(G12:G16) -> 5 | H11: =SUM(H12:H16) -> 3
E12: Use case diagram | F12: 1 | G12: 1 | H12: 0
E13: Activity diagram | F13: 1 | G13: 1 | H13: 1 | J13: Velocity Chart
E14: Update the GUI | F14: 2 | G14: 1 | H14: 0
E15: Write the code | F15: 1 | G15: 2 | H15: 1
E16: Test | F16: 2 | G16: 0 | H16: 1
A17: 10 | B17: Low | C17: Dima | D17: =Final!C20 -> 20 | E17: As an administrator, I want to be able to select the prices of different cars, in order to control prices. | F17: =SUM(F18:F22) -> 7 | G17: =SUM(G18:G22) -> 4 | H17: =SUM(H18:H22) -> 2
E18: Create Edit Cars Tab in GUI | F18: 1 | G18: 0 | H18: 0
E19: Implementing add a car button and functions for this button | F19: 2 | G19: 1 | H19: 0
E20: Implementing edit a car button and functions for this button | F20: 1 | G20: 2 | H20: 0
E21: SQL statements to get the useful data from the database | F21: 2 | G21: 1 | H21: 1
E22: Testing | F22: 1 | G22: 0 | H22: 1
A23: 14 | B23: Medium | C23: Nicoleta | D23: =Final!C24 -> 10 | E23: As a user, I want to be able to add money to my wallet | F23: =SUM(F24:F28) -> 8 | G23: =SUM(G24:G28) -> 3 | H23: =SUM(H24:H28) -> 1
E24: Use case diagram | F24: 1 | G24: 0 | H24: 0
E25: Activity diagram | F25: 1 | G25: 0 | H25: 0
E26: Update the GUI | F26: 2 | G26: 1 | H26: 0
E27: Write the code | F27: 2 | G27: 1 | H27: 0
E28: Test | F28: 2 | G28: 1 | H28: 1
A29: Total | D29: =SUBTOTAL(109,Table14567[Estimate]) -> 45 | F29: =SUM(F11,F17,F23) -> 22 | G29: =SUM(G11,G17,G23) -> 12 | H29: =SUM(H11,H17,H23) -> 6
F30: =SUM(Table14567[[#Totals],[Day 1]:[Day 3]]) -> 40

Sheet Sprint 5
E1: Group 2 | F1: Product Backlog
E2: Rental Car Project | F2: "Europcar"
E3: Deadline Estimate / Today | F3: 43623 | G3: =TODAY() -> 43623 | H3: Left days: | I3: =F3-G3 -> 0
E4: How many percent are done | F4: =(COUNTA(F12:F16,F18:F28,F30:F37,G12:G16,G18:G28,G30:G37,H12:H16,H18:H28,H30:H37))/(COUNTA(E12:E16,E18:E28,E30:E37)*3)*100 -> 100
E5: ? | F5: ? | H5: Done
E6: ? | F6: ? | G6: ? | H6: In Progres
E7: Number of hours Estimate/Actual | F7: =Table145678[[#Totals],[Estimate]] -> 5 | G7: =SUM(Table145678[[#Totals],[Day 1]:[Day 3]]) -> 54.75 | H7: Not Started
A9: Product Backlog
A10: ID | B10: Priority | C10: Responsible | D10: Estimate | E10: Item | F10: Day 1 | G10: Day 2 | H10: Day 3
A11: 7 | B11: Medium | C11: Justinas | D11: =Final!C17 -> 5 | E11: As a user, I want to be able to cancel my reservation in order to not rent a vehicle. | F11: =SUM(F12:F16) -> 5 | G11: =SUM(G12:G16) -> 2 | H11: =SUM(H12:H16) -> 3
E12: Use case diagram | F12: 0 | G12: 0 | H12: 3
E13: Activity diagram | F13: 0 | G13: 2 | H13: 0 | J13: Velocity Chart
E14: Update the GUI | F14: 2 | G14: 0 | H14: 0
E15: Write the code | F15: 2 | G15: 0 | H15: 0
E16: Test | F16: 1 | G16: 0 | H16: 0
E17: Project Report | F17: =SUM(F18:F28) -> 9.5 | G17: =SUM(G18:G28) -> 7 | H17: =SUM(H18:H28) -> 10.75
E18: Intoduction | F18: 1 | G18: 0 | H18: 0.25
E19: Requirements | F19: 0.5 | G19: 0 | H19: 1.5
E20: Analysis | F20: 1 | G20: 1 | H20: 3
E21: Design | F21: 2 | G21: 3 | H21: 3
E22: Implementation | F22: 1 | G22: 2 | H22: 1
E23: Test | F23: 3 | G23: 1 | H23: 0.5
E24: Result and Discusion | F24: 0.5 | G24: 0 | H24: 0
E25: Conclusion | F25: 0.5 | G25: 0 | H25: 0
E26: Project Future | F26: 0 | G26: 0 | H26: 0.5
E27: Source of Information | F27: 0 | G27: 0 | H27: 0.5
E28: Appendices | F28: 0 | G28: 0 | H28: 0.5
E29: Process Report | F29: =SUM(F30:F37) -> 6.75 | G29: =SUM(G30:G37) -> 3.25 | H29: =SUM(H30:H37) -> 7.5
E30: Introduction | F30: 1 | G30: 0.25 | H30: 0.25
E31: Group Description | F31: 1.5 | G31: 0 | H31: 0.25
E32: Gorup Initiation | F32: 0.5 | G32: 0 | H32: 1.5
E33: Group Execution | F33: 2 | G33: 1 | H33: 2
E34: Personal Reflection | F34: 1 | G34: 1 | H34: 1
E35: Supervison | F35: 0.5 | G35: 1 | H35: 1.5
E36: Conclusion | F36: 0.25 | G36: 0 | H36: 1
A38: Total | D38: =SUBTOTAL(109,Table145678[Estimate]) -> 5 | F38: =SUM(F11,F17,F29) -> 21.25 | G38: =SUM(G11,G17,G29) -> 12.25 | H38: =SUM(H11,H17,H29) -> 21.25
F39: =SUM(Table145678[[#Totals],[Day 1]:[Day 3]]) -> 54.75

Sheet r1
A6: Final
A7: Total Actual | C7: =Table1[[#Totals],[Day 1]]+D7 -> 183.45 | D7: =Table1[[#Totals],[Day 2]]+E7 -> 103 | E7: =Table1[[#Totals],[Day 3]] -> 46.25 | F7: 0
A8: Total Planned | C8: =Table1[[#Totals],[Estimate]] -> 185 | D8: =C8/3*2 -> 123.33333 | E8: =C8/3 -> 61.666667 | F8: 0
A9: Total Planned | C9: =Table1[[#Totals],[Estimate]] -> 185 | D9: =C9/3*2 -> 123.33333 | E9: =C9/3 -> 61.666667 | F9: 1
A10: Sprint 1
A11: Total Actual | C11: =C12 -> 55 | D11: =Table14[[#Totals],[Day 1]] -> 30 | E11: =Table14[[#Totals],[Day 2]] -> 20.5 | F11: =Table14[[#Totals],[Day 3]] -> 19
A12: Total | C12: =Table14[[#Totals],[Estimate]] -> 55 | D12: =C12 - D11 -> 25 | E12: =D12 - E11 -> 4.5 | F12: =E12 - F11 -> -14.5
A13: Expected | C13: =Table14[[#Totals],[Estimate]] -> 55 | D13: =C13 - $C13/3 -> 36.666667 | E13: =D13 - $C13/3 -> 18.333333 | F13: =E13 - $C13/3 -> 0
A14: Sprint 2
A15: Total Actual | C15: =C16 -> 60 | D15: =Table145[[#Totals],[Day 1]] -> 14.45 | E15: =Table145[[#Totals],[Day 2]] -> 8.25 | F15: =Table145[[#Totals],[Day 3]] -> 6.25
A16: Total | C16: =Table145[[#Totals],[Estimate]] -> 60 | D16: =C16 - D15 -> 45.55 | E16: =D16 - E15 -> 37.3 | F16: =E16 - F15 -> 31.05
A17: Expected | C17: =Table145[[#Totals],[Estimate]] -> 60 | D17: =C17 - $C17/3 -> 40 | E17: =D17 - $C17/3 -> 20 | F17: =E17 - $C17/3 -> 0
A18: Sprint 3
A19: Total Actual | C19: =C20 -> 20 | D19: =Table1456[[#Totals],[Day 1]] -> 9 | E19: =Table1456[[#Totals],[Day 2]] -> 9 | F19: =Table1456[[#Totals],[Day 2]] -> 9
A20: Total | C20: =Table1456[[#Totals],[Estimate]] -> 20 | D20: =C20/3+E20 -> 13.333333 | E20: =C20/3 -> 6.6666667 | F20: 0
A21: Sprint 4
A22: Total Actual | C22: =C23 -> 45 | D22: =Table14567[[#Totals],[Day 1]] -> 22 | E22: =Table14567[[#Totals],[Day 2]] -> 12 | F22: =Table14567[[#Totals],[Day 3]] -> 6
A23: Total | C23: =Table14567[[#Totals],[Estimate]] -> 45 | D23: =C23/3+E23 -> 30 | E23: =C23/3 -> 15 | F23: 0
A24: Sprint 5
A25: Total Actual | C25: =Table14[[#Totals],[Day 1]] -> 30 | D25: =SUM('Sprint 1'!M26:O26) -> 0 | E25: =Table14[[#Totals],[Day 3]] -> 19 | F25: =0 -> 0
A26: Total | C26: =Table14[[#Totals],[Estimate]] -> 55 | D26: =C26/3+E26 -> 36.666667 | E26: =C26/3 -> 18.333333 | F26: 0
A27: Sprint 6
A28: Total Actual | C28: =Table14[[#Totals],[Day 1]] -> 30 | D28: =SUM('Sprint 1'!M29:O29) -> 0 | E28: =Table14[[#Totals],[Day 3]] -> 19 | F28: =0 -> 0
A29: Total | C29: =Table14[[#Totals],[Estimate]] -> 55 | D29: =C29/3+E29 -> 36.666667 | E29: =C29/3 -> 18.333333 | F29: 0
A30: Sprint 7
A31: Total Actual | C31: =Table14[[#Totals],[Day 1]] -> 30 | D31: =SUM('Sprint 1'!M32:O32) -> 0 | E31: =Table14[[#Totals],[Day 3]] -> 19 | F31: =0 -> 0
A32: Total | C32: =Table14[[#Totals],[Estimate]] -> 55 | D32: =C32/3+E32 -> 36.666667 | E32: =C32/3 -> 18.333333 | F32: 0
J37: Session | K37: Date | L37: Content | M37: Preparation | N37: Resources and activities | O37: Links
J38: Sprint #1, day 2 | K38: 04 Apr 08:20 – 16:05 | L38: Every group has a Daily SCRUM meeting(documented outcome: updated burndown chart, log/resume if task responsible or ressources changed) See e.g. https://agilevelocity.com/scrummaster/daily-scrum-cheat-sheet/ | M38: Finish your tasks | O38: https://agilevelocity.com/scrummaster/daily-scrum-cheat-sheet/
J39: Sprint #1, day 3 | K39: 11 Apr 08:20 – 16:05 | L39: Every group has a Daily SCRUM meeting (documented outcome: updated burndown chart, log/resume if task responsible or ressources changed) | M39: Finish your tasks
J40: Sprint #1 ends, Sprint #2 starts | K40: 25 Apr 08:20 – 16:05 | L40: Every group has a Sprint 1 review meeting (documented outcome: list of the approved or rejected product backlog items (completed/not completed) from Product owners after the presentation, updated burndown chart, Log/summary for meeting, Completed and tested code, Diagrams and documentation/work papers) a Sprint 1 retrospective meeting (documented outcome: list of aggreed start-stop-continue areas, Log/summary for meeting) some time to update the Product backlog (outcome: updated product backlog with completed items, newly rearranged items, new items, deleted items - and reestimated items and higher priority items described in more details) a Sprint 2 planning meeting (documented outcome: Sprint 2 goal, Sprint 2 Backlog including responsible person for each task, Log/summary for the meeting and expected UP phase) About review, see e.g. link About retrospective, see e.g. link About planning, see e.g. link | M40: Finish Sprint 1 tasks - after meetings, upload documented outcome to your group folder | O40: https://codehollow.com/scrum-meeting-templates/sprint-review-template/ https://agilevelocity.com/scrummaster/retrospective-cheat-sheet/ https://www.leadingagile.com/2012/08/simple-cheat-sheet-to-sprint-planning-meeting/
J41: Sprint #2, day 2 | K41: 02 May 08:20 – 16:05 | L41: Daily SCRUM meeting
J42: Sprint #2, day 3 | K42: 09 May 08:20 – 16:05 | L42: Daily SCRUM meeting
J43: Sprint #2, ends, Sprint #3 starts | K43: 16 May 08:20 – 16:05 | L43: Review meeting Retrospective meeting Update Product backlog Sprint planning meeting
J44: Sprint #3, day 2 | K44: 20 May 08:20 – 16:05
J45: Sprint #3, day 3 | K45: 21 May 08:20 – 16:05
J46: Sprint #3 ends, Sprint #4 starts | K46: 22 May 08:20 – 16:05
J47: Sprint #4 day 2 | K47: 23 May 08:20 – 16:05
J48: Sprint #4, day 3 | K48: 24 May 08:20 – 16:05
J49: Sprint #4, ends, Sprint #5 starts | K49: 27 May 08:20 – 16:05
...

Sheet r1 (2)
O1: 43630
O2: 43631
O3: 43632
O4: 43633
C5: Day 1 | D5: Day 2 | E5: Day 3 | F5: Day 4 | O5: 43634
A6: Final
A7: Total Actual | C7: =Table1[[#Totals],[Day 1]]+D7 -> 183.45 | D7: =Table1[[#Totals],[Day 2]]+E7 -> 103 | E7: =Table1[[#Totals],[Day 3]] -> 46.25 | F7: 0 | J7: Day 1 | K7: Day 2 | L7: Day 3 | M7: Day4
A8: Total Planned | C8: =Table1[[#Totals],[Estimate]] -> 185 | D8: =C8/3*2 -> 123.33333 | E8: =C8/3 -> 61.666667 | F8: 0
A9: Total Planned | C9: =Table1[[#Totals],[Estimate]] -> 185 | D9: =C9/3*2 -> 123.33333 | E9: =C9/3 -> 61.666667 | F9: 1 | J9: =Table1[[#Totals],[Estimate]] -> 185 | K9: =J9-L9 -> 123.33333 | L9: =J9/3 -> 61.666667 | M9: 0
A10: Sprint 1 | J10: 0 | K10: =Table1[[#Totals],[Day 2]] -> 56.75 | L10: =Table1[[#Totals],[Day 3]] -> 46.25 | M10: 0
B11: 0 | C11: =Table14[[#Totals],[Day 1]] -> 30 | D11: =Table14[[#Totals],[Day 2]] -> 20.5 | E11: =Table14[[#Totals],[Day 3]] -> 19 | F11: 0
A12: Total
B13: =C13+E13 -> 73.333333 | C13: =Table14[[#Totals],[Estimate]] -> 55 | D13: =C13-E13 -> 36.666667 | E13: =$C13/3 -> 18.333333 | F13: =E13 - $C13/3 -> 0
A14: Sprint 2 | J14: Day 1 | K14: Day 2 | L14: Day 3 | M14: Day 4 | N14: Day 5 | O14: Day 6 | P14: Day 7 | Q14: Day 8 | R14: Day 9 | S14: Day 10 | T14: Day 11 | U14: Day 12 | V14: Day 13 | W14: Day 14 | X14: Day 15 | Y14: Day 16 | Z14: Day 17 | AA14: Day 18 | AB14: Day 19 | AC14: Day 20 | AD14: Day 21 | AE14: Day 22
A15: Total Actual | C15: =C16 -> 60 | D15: =Table145[[#Totals],[Day 1]] -> 14.45 | E15: =Table145[[#Totals],[Day 2]] -> 8.25 | F15: =Table145[[#Totals],[Day 3]] -> 6.25 | J15: 185 | K15: =J15-AE15 -> 176.19048 | L15: =K15-AE15 -> 167.38095 | M15: =L15-AE15 -> 158.57143 | N15: =M15-AE15 -> 149.7619 | O15: =N15-AE15 -> 140.95238 | P15: =O15-AE15 -> 132.14286 | Q15: =P15-AE15 -> 123.33333 | R15: =Q15-AE15 -> 114.52381 | S15: =R15-AE15 -> 105.71429 | T15: =S15-AE15 -> 96.904762 | U15: =T15-AE15 -> 88.095238 | V15: =U15-AE15 -> 79.285714 | W15: =V15-AE15 -> 70.47619 | X15: =W15-AE15 -> 61.666667 | Y15: =X15-AE15 -> 52.857143 | Z15: =Y15-AE15 -> 44.047619 | AA15: =Z15-AE15 -> 35.238095 | AB15: =AA15-AE15 -> 26.428571 | AC15: =AB15-AE15 -> 17.619048 | AD15: =AC15-AE15 -> 8.8095238 | AE15: =J15/21 -> 8.8095238
A16: Total | C16: =Table145[[#Totals],[Estimate]] -> 60 | D16: =C16 - D15 -> 45.55 | E16: =D16 - E15 -> 37.3 | F16: =E16 - F15 -> 31.05 | J16: 54 | K16: 3 | L16: 24 | M16: 2 | N16: 23 | O16: 3 | P16: 2 | Q16: 1 | R16: 0 | S16: 2 | T16: 23 | U16: 3 | V16: 3 | W16: 3 | X16: 4 | Z16: 2 | AA16: 2 | AB16: 4 | AC16: 5 | AD16: 2 | AE16: 3
A17: Expected | C17: =Table145[[#Totals],[Estimate]] -> 60 | D17: =C17 - $C17/3 -> 40 | E17: =D17 - $C17/3 -> 20 | F17: =E17 - $C17/3 -> 0
A18: Sprint 3
A19: Total Actual | C19: =C20 -> 20 | D19: =Table1456[[#Totals],[Day 1]] -> 9 | E19: =Table1456[[#Totals],[Day 2]] -> 9 | F19: =Table1456[[#Totals],[Day 2]] -> 9
A20: Total | C20: =Table1456[[#Totals],[Estimate]] -> 20 | D20: =C20/3+E20 -> 13.333333 | E20: =C20/3 -> 6.6666667 | F20: 0
A21: Sprint 4
A22: Total Actual | C22: =C23 -> 45 | D22: =Table14567[[#Totals],[Day 1]] -> 22 | E22: =Table14567[[#Totals],[Day 2]] -> 12 | F22: =Table14567[[#Totals],[Day 3]] -> 6
A23: Total | C23: =Table14567[[#Totals],[Estimate]] -> 45 | D23: =C23/3+E23 -> 30 | E23: =C23/3 -> 15 | F23: 0
A24: Sprint 5
A25: Total Actual | C25: =Table14[[#Totals],[Day 1]] -> 30 | D25: =SUM('Sprint 1'!M26:O26) -> 0 | E25: =Table14[[#Totals],[Day 3]] -> 19 | F25: =0 -> 0
A26: Total | C26: =Table14[[#Totals],[Estimate]] -> 55 | D26: =C26/3+E26 -> 36.666667 | E26: =C26/3 -> 18.333333 | F26: 0
A27: Sprint 6
A28: Total Actual | C28: =Table14[[#Totals],[Day 1]] -> 30 | D28: =SUM('Sprint 1'!M29:O29) -> 0 | E28: =Table14[[#Totals],[Day 3]] -> 19 | F28: =0 -> 0
A29: Total | C29: =Table14[[#Totals],[Estimate]] -> 55 | D29: =C29/3+E29 -> 36.666667 | E29: =C29/3 -> 18.333333 | F29: 0
A30: Sprint 7
A31: Total Actual | C31: =Table14[[#Totals],[Day 1]] -> 30 | D31: =SUM('Sprint 1'!M32:O32) -> 0 | E31: =Table14[[#Totals],[Day 3]] -> 19 | F31: =0 -> 0
A32: Total | C32: =Table14[[#Totals],[Estimate]] -> 55 | D32: =C32/3+E32 -> 36.666667 | E32: =C32/3 -> 18.333333 | F32: 0
J37: Session | K37: Date | L37: Content | M37: Preparation | N37: Resources and activities | O37: Links
J38: Sprint #1, day 2 | K38: 04 Apr 08:20 – 16:05 | L38: Every group has a Daily SCRUM meeting(documented outcome: updated burndown chart, log/resume if task responsible or ressources changed) See e.g. https://agilevelocity.com/scrummaster/daily-scrum-cheat-sheet/ | M38: Finish your tasks | O38: https://agilevelocity.com/scrummaster/daily-scrum-cheat-sheet/
J39: Sprint #1, day 3 | K39: 11 Apr 08:20 – 16:05 | L39: Every group has a Daily SCRUM meeting (documented outcome: updated burndown chart, log/resume if task responsible or ressources changed) | M39: Finish your tasks
J40: Sprint #1 ends, Sprint #2 starts | K40: 25 Apr 08:20 – 16:05 | L40: Every group has a Sprint 1 review meeting (documented outcome: list of the approved or rejected product backlog items (completed/not completed) from Product owners after the presentation, updated burndown chart, Log/summary for meeting, Completed and tested code, Diagrams and documentation/work papers) a Sprint 1 retrospective meeting (documented outcome: list of aggreed start-stop-continue areas, Log/summary for meeting) some time to update the Product backlog (outcome: updated product backlog with completed items, newly rearranged items, new items, deleted items - and reestimated items and higher priority items described in more details) a Sprint 2 planning meeting (documented outcome: Sprint 2 goal, Sprint 2 Backlog including responsible person for each task, Log/summary for the meeting and expected UP phase) About review, see e.g. link About retrospective, see e.g. link About planning, see e.g. link | M40: Finish Sprint 1 tasks - after meetings, upload documented outcome to your group folder | O40: https://codehollow.com/scrum-meeting-templates/sprint-review-template/ https://agilevelocity.com/scrummaster/retrospective-cheat-sheet/ https://www.leadingagile.com/2012/08/simple-cheat-sheet-to-sprint-planning-meeting/
J41: Sprint #2, day 2 | K41: 02 May 08:20 – 16:05 | L41: Daily SCRUM meeting
J42: Sprint #2, day 3 | K42: 09 May 08:20 – 16:05 | L42: Daily SCRUM meeting
J43: Sprint #2, ends, Sprint #3 starts | K43: 16 May 08:20 – 16:05 | L43: Review meeting Retrospective meeting Update Product backlog Sprint planning meeting
J44: Sprint #3, day 2 | K44: 20 May 08:20 – 16:05
...
